C:\Users\topci\Desktop\bitirmeProjesi\bitirmeProjem\bitirmeProjem\settings.py changed, reloading.
Watching for file changes with StatReloader
C:\Users\topci\Desktop\bitirmeProjesi\bitirmeProjem\urunler\views.py changed, reloading.
Watching for file changes with StatReloader
C:\Users\topci\Desktop\bitirmeProjesi\bitirmeProjem\urunler\views.py changed, reloading.
Watching for file changes with StatReloader
C:\Users\topci\Desktop\bitirmeProjesi\bitirmeProjem\urunler\views.py changed, reloading.
Watching for file changes with StatReloader
C:\Users\topci\Desktop\bitirmeProjesi\bitirmeProjem\urunler\views.py changed, reloading.
Watching for file changes with StatReloader
C:\Users\topci\Desktop\bitirmeProjesi\bitirmeProjem\urunler\views.py changed, reloading.
Watching for file changes with StatReloader
C:\Users\topci\Desktop\bitirmeProjesi\bitirmeProjem\urunler\views.py changed, reloading.
Watching for file changes with StatReloader
C:\Users\topci\Desktop\bitirmeProjesi\bitirmeProjem\urunler\views.py changed, reloading.
Watching for file changes with StatReloader
C:\Users\topci\Desktop\bitirmeProjesi\bitirmeProjem\urunler\views.py changed, reloading.
Watching for file changes with StatReloader
C:\Users\topci\Desktop\bitirmeProjesi\bitirmeProjem\urunler\views.py changed, reloading.
Watching for file changes with StatReloader
C:\Users\topci\Desktop\bitirmeProjesi\bitirmeProjem\urunler\views.py changed, reloading.
Watching for file changes with StatReloader
C:\Users\topci\Desktop\bitirmeProjesi\bitirmeProjem\urunler\views.py changed, reloading.
Watching for file changes with StatReloader
C:\Users\topci\Desktop\bitirmeProjesi\bitirmeProjem\bitirmeProjem\urls.py changed, reloading.
Watching for file changes with StatReloader
C:\Users\topci\Desktop\bitirmeProjesi\bitirmeProjem\bitirmeProjem\urls.py changed, reloading.
Watching for file changes with StatReloader
C:\Users\topci\Desktop\bitirmeProjesi\bitirmeProjem\bitirmeProjem\urls.py changed, reloading.
Watching for file changes with StatReloader
C:\Users\topci\Desktop\bitirmeProjesi\bitirmeProjem\bitirmeProjem\urls.py changed, reloading.
Watching for file changes with StatReloader
C:\Users\topci\Desktop\bitirmeProjesi\bitirmeProjem\bitirmeProjem\urls.py changed, reloading.
Watching for file changes with StatReloader
C:\Users\topci\Desktop\bitirmeProjesi\bitirmeProjem\bitirmeProjem\urls.py changed, reloading.
Watching for file changes with StatReloader
C:\Users\topci\Desktop\bitirmeProjesi\bitirmeProjem\bitirmeProjem\urls.py changed, reloading.
Watching for file changes with StatReloader
C:\Users\topci\Desktop\bitirmeProjesi\bitirmeProjem\bitirmeProjem\urls.py changed, reloading.
Watching for file changes with StatReloader
C:\Users\topci\Desktop\bitirmeProjesi\bitirmeProjem\bitirmeProjem\urls.py changed, reloading.
Watching for file changes with StatReloader
C:\Users\topci\Desktop\bitirmeProjesi\bitirmeProjem\bitirmeProjem\urls.py changed, reloading.
Watching for file changes with StatReloader
C:\Users\topci\Desktop\bitirmeProjesi\bitirmeProjem\bitirmeProjem\urls.py changed, reloading.
Watching for file changes with StatReloader
C:\Users\topci\Desktop\bitirmeProjesi\bitirmeProjem\bitirmeProjem\urls.py changed, reloading.
Watching for file changes with StatReloader
C:\Users\topci\Desktop\bitirmeProjesi\bitirmeProjem\urunler\views.py changed, reloading.
Watching for file changes with StatReloader
C:\Users\topci\Desktop\bitirmeProjesi\bitirmeProjem\urunler\views.py changed, reloading.
Watching for file changes with StatReloader
C:\Users\topci\Desktop\bitirmeProjesi\bitirmeProjem\urunler\views.py changed, reloading.
Watching for file changes with StatReloader
C:\Users\topci\Desktop\bitirmeProjesi\bitirmeProjem\urunler\views.py changed, reloading.
Watching for file changes with StatReloader
C:\Users\topci\Desktop\bitirmeProjesi\bitirmeProjem\urunler\views.py changed, reloading.
Watching for file changes with StatReloader
C:\Users\topci\Desktop\bitirmeProjesi\bitirmeProjem\urunler\views.py changed, reloading.
Watching for file changes with StatReloader
C:\Users\topci\Desktop\bitirmeProjesi\bitirmeProjem\urunler\views.py changed, reloading.
Watching for file changes with StatReloader
C:\Users\topci\Desktop\bitirmeProjesi\bitirmeProjem\urunler\views.py changed, reloading.
Watching for file changes with StatReloader
C:\Users\topci\Desktop\bitirmeProjesi\bitirmeProjem\urunler\views.py changed, reloading.
Watching for file changes with StatReloader
C:\Users\topci\Desktop\bitirmeProjesi\bitirmeProjem\bitirmeProjem\urls.py changed, reloading.
Watching for file changes with StatReloader
C:\Users\topci\Desktop\bitirmeProjesi\bitirmeProjem\bitirmeProjem\urls.py changed, reloading.
Watching for file changes with StatReloader
C:\Users\topci\Desktop\bitirmeProjesi\bitirmeProjem\bitirmeProjem\urls.py changed, reloading.
Watching for file changes with StatReloader
C:\Users\topci\Desktop\bitirmeProjesi\bitirmeProjem\bitirmeProjem\urls.py changed, reloading.
Watching for file changes with StatReloader
OK: /
Traceback (most recent call last):
  File "C:\Users\topci\AppData\Local\Programs\Python\Python38\lib\site-packages\django\db\models\fields\__init__.py", line 2018, in get_prep_value
    return int(value)
TypeError: int() argument must be a string, a bytes-like object or a number, not 'SimpleLazyObject'

The above exception was the direct cause of the following exception:

Traceback (most recent call last):
  File "C:\Users\topci\AppData\Local\Programs\Python\Python38\lib\site-packages\django\core\handlers\exception.py", line 56, in inner
    response = get_response(request)
  File "C:\Users\topci\AppData\Local\Programs\Python\Python38\lib\site-packages\django\core\handlers\base.py", line 197, in _get_response
    response = wrapped_callback(request, *callback_args, **callback_kwargs)
  File "C:\Users\topci\Desktop\bitirmeProjesi\bitirmeProjem\urunler\views.py", line 188, in index
    uruns = Sepet.objects.filter(ekleyen = request.user, odendiMi = False)
  File "C:\Users\topci\AppData\Local\Programs\Python\Python38\lib\site-packages\django\db\models\manager.py", line 85, in manager_method
    return getattr(self.get_queryset(), name)(*args, **kwargs)
  File "C:\Users\topci\AppData\Local\Programs\Python\Python38\lib\site-packages\django\db\models\query.py", line 1421, in filter
    return self._filter_or_exclude(False, args, kwargs)
  File "C:\Users\topci\AppData\Local\Programs\Python\Python38\lib\site-packages\django\db\models\query.py", line 1439, in _filter_or_exclude
    clone._filter_or_exclude_inplace(negate, args, kwargs)
  File "C:\Users\topci\AppData\Local\Programs\Python\Python38\lib\site-packages\django\db\models\query.py", line 1446, in _filter_or_exclude_inplace
    self._query.add_q(Q(*args, **kwargs))
  File "C:\Users\topci\AppData\Local\Programs\Python\Python38\lib\site-packages\django\db\models\sql\query.py", line 1532, in add_q
    clause, _ = self._add_q(q_object, self.used_aliases)
  File "C:\Users\topci\AppData\Local\Programs\Python\Python38\lib\site-packages\django\db\models\sql\query.py", line 1562, in _add_q
    child_clause, needed_inner = self.build_filter(
  File "C:\Users\topci\AppData\Local\Programs\Python\Python38\lib\site-packages\django\db\models\sql\query.py", line 1478, in build_filter
    condition = self.build_lookup(lookups, col, value)
  File "C:\Users\topci\AppData\Local\Programs\Python\Python38\lib\site-packages\django\db\models\sql\query.py", line 1303, in build_lookup
    lookup = lookup_class(lhs, rhs)
  File "C:\Users\topci\AppData\Local\Programs\Python\Python38\lib\site-packages\django\db\models\lookups.py", line 27, in __init__
    self.rhs = self.get_prep_lookup()
  File "C:\Users\topci\AppData\Local\Programs\Python\Python38\lib\site-packages\django\db\models\fields\related_lookups.py", line 166, in get_prep_lookup
    self.rhs = target_field.get_prep_value(self.rhs)
  File "C:\Users\topci\AppData\Local\Programs\Python\Python38\lib\site-packages\django\db\models\fields\__init__.py", line 2020, in get_prep_value
    raise e.__class__(
TypeError: Field 'id' expected a number but got <SimpleLazyObject: <django.contrib.auth.models.AnonymousUser object at 0x000001E719CDEB20>>.
OK: /
Traceback (most recent call last):
  File "C:\Users\topci\AppData\Local\Programs\Python\Python38\lib\site-packages\django\db\models\fields\__init__.py", line 2018, in get_prep_value
    return int(value)
TypeError: int() argument must be a string, a bytes-like object or a number, not 'SimpleLazyObject'

The above exception was the direct cause of the following exception:

Traceback (most recent call last):
  File "C:\Users\topci\AppData\Local\Programs\Python\Python38\lib\site-packages\django\core\handlers\exception.py", line 56, in inner
    response = get_response(request)
  File "C:\Users\topci\AppData\Local\Programs\Python\Python38\lib\site-packages\django\core\handlers\base.py", line 197, in _get_response
    response = wrapped_callback(request, *callback_args, **callback_kwargs)
  File "C:\Users\topci\Desktop\bitirmeProjesi\bitirmeProjem\urunler\views.py", line 188, in index
    uruns = Sepet.objects.filter(ekleyen = request.user, odendiMi = False)
  File "C:\Users\topci\AppData\Local\Programs\Python\Python38\lib\site-packages\django\db\models\manager.py", line 85, in manager_method
    return getattr(self.get_queryset(), name)(*args, **kwargs)
  File "C:\Users\topci\AppData\Local\Programs\Python\Python38\lib\site-packages\django\db\models\query.py", line 1421, in filter
    return self._filter_or_exclude(False, args, kwargs)
  File "C:\Users\topci\AppData\Local\Programs\Python\Python38\lib\site-packages\django\db\models\query.py", line 1439, in _filter_or_exclude
    clone._filter_or_exclude_inplace(negate, args, kwargs)
  File "C:\Users\topci\AppData\Local\Programs\Python\Python38\lib\site-packages\django\db\models\query.py", line 1446, in _filter_or_exclude_inplace
    self._query.add_q(Q(*args, **kwargs))
  File "C:\Users\topci\AppData\Local\Programs\Python\Python38\lib\site-packages\django\db\models\sql\query.py", line 1532, in add_q
    clause, _ = self._add_q(q_object, self.used_aliases)
  File "C:\Users\topci\AppData\Local\Programs\Python\Python38\lib\site-packages\django\db\models\sql\query.py", line 1562, in _add_q
    child_clause, needed_inner = self.build_filter(
  File "C:\Users\topci\AppData\Local\Programs\Python\Python38\lib\site-packages\django\db\models\sql\query.py", line 1478, in build_filter
    condition = self.build_lookup(lookups, col, value)
  File "C:\Users\topci\AppData\Local\Programs\Python\Python38\lib\site-packages\django\db\models\sql\query.py", line 1303, in build_lookup
    lookup = lookup_class(lhs, rhs)
  File "C:\Users\topci\AppData\Local\Programs\Python\Python38\lib\site-packages\django\db\models\lookups.py", line 27, in __init__
    self.rhs = self.get_prep_lookup()
  File "C:\Users\topci\AppData\Local\Programs\Python\Python38\lib\site-packages\django\db\models\fields\related_lookups.py", line 166, in get_prep_lookup
    self.rhs = target_field.get_prep_value(self.rhs)
  File "C:\Users\topci\AppData\Local\Programs\Python\Python38\lib\site-packages\django\db\models\fields\__init__.py", line 2020, in get_prep_value
    raise e.__class__(
TypeError: Field 'id' expected a number but got <SimpleLazyObject: <django.contrib.auth.models.AnonymousUser object at 0x000001E719D38EE0>>.
OK: /
Traceback (most recent call last):
  File "C:\Users\topci\AppData\Local\Programs\Python\Python38\lib\site-packages\django\db\models\fields\__init__.py", line 2018, in get_prep_value
    return int(value)
TypeError: int() argument must be a string, a bytes-like object or a number, not 'SimpleLazyObject'

The above exception was the direct cause of the following exception:

Traceback (most recent call last):
  File "C:\Users\topci\AppData\Local\Programs\Python\Python38\lib\site-packages\django\core\handlers\exception.py", line 56, in inner
    response = get_response(request)
  File "C:\Users\topci\AppData\Local\Programs\Python\Python38\lib\site-packages\django\core\handlers\base.py", line 197, in _get_response
    response = wrapped_callback(request, *callback_args, **callback_kwargs)
  File "C:\Users\topci\Desktop\bitirmeProjesi\bitirmeProjem\urunler\views.py", line 188, in index
    uruns = Sepet.objects.filter(ekleyen = request.user, odendiMi = False)
  File "C:\Users\topci\AppData\Local\Programs\Python\Python38\lib\site-packages\django\db\models\manager.py", line 85, in manager_method
    return getattr(self.get_queryset(), name)(*args, **kwargs)
  File "C:\Users\topci\AppData\Local\Programs\Python\Python38\lib\site-packages\django\db\models\query.py", line 1421, in filter
    return self._filter_or_exclude(False, args, kwargs)
  File "C:\Users\topci\AppData\Local\Programs\Python\Python38\lib\site-packages\django\db\models\query.py", line 1439, in _filter_or_exclude
    clone._filter_or_exclude_inplace(negate, args, kwargs)
  File "C:\Users\topci\AppData\Local\Programs\Python\Python38\lib\site-packages\django\db\models\query.py", line 1446, in _filter_or_exclude_inplace
    self._query.add_q(Q(*args, **kwargs))
  File "C:\Users\topci\AppData\Local\Programs\Python\Python38\lib\site-packages\django\db\models\sql\query.py", line 1532, in add_q
    clause, _ = self._add_q(q_object, self.used_aliases)
  File "C:\Users\topci\AppData\Local\Programs\Python\Python38\lib\site-packages\django\db\models\sql\query.py", line 1562, in _add_q
    child_clause, needed_inner = self.build_filter(
  File "C:\Users\topci\AppData\Local\Programs\Python\Python38\lib\site-packages\django\db\models\sql\query.py", line 1478, in build_filter
    condition = self.build_lookup(lookups, col, value)
  File "C:\Users\topci\AppData\Local\Programs\Python\Python38\lib\site-packages\django\db\models\sql\query.py", line 1303, in build_lookup
    lookup = lookup_class(lhs, rhs)
  File "C:\Users\topci\AppData\Local\Programs\Python\Python38\lib\site-packages\django\db\models\lookups.py", line 27, in __init__
    self.rhs = self.get_prep_lookup()
  File "C:\Users\topci\AppData\Local\Programs\Python\Python38\lib\site-packages\django\db\models\fields\related_lookups.py", line 166, in get_prep_lookup
    self.rhs = target_field.get_prep_value(self.rhs)
  File "C:\Users\topci\AppData\Local\Programs\Python\Python38\lib\site-packages\django\db\models\fields\__init__.py", line 2020, in get_prep_value
    raise e.__class__(
TypeError: Field 'id' expected a number but got <SimpleLazyObject: <django.contrib.auth.models.AnonymousUser object at 0x000001E719C10400>>.
OK: /
Traceback (most recent call last):
  File "C:\Users\topci\AppData\Local\Programs\Python\Python38\lib\site-packages\django\db\models\fields\__init__.py", line 2018, in get_prep_value
    return int(value)
TypeError: int() argument must be a string, a bytes-like object or a number, not 'SimpleLazyObject'

The above exception was the direct cause of the following exception:

Traceback (most recent call last):
  File "C:\Users\topci\AppData\Local\Programs\Python\Python38\lib\site-packages\django\core\handlers\exception.py", line 56, in inner
    response = get_response(request)
  File "C:\Users\topci\AppData\Local\Programs\Python\Python38\lib\site-packages\django\core\handlers\base.py", line 197, in _get_response
    response = wrapped_callback(request, *callback_args, **callback_kwargs)
  File "C:\Users\topci\Desktop\bitirmeProjesi\bitirmeProjem\urunler\views.py", line 188, in index
    uruns = Sepet.objects.filter(ekleyen = request.user, odendiMi = False)
  File "C:\Users\topci\AppData\Local\Programs\Python\Python38\lib\site-packages\django\db\models\manager.py", line 85, in manager_method
    return getattr(self.get_queryset(), name)(*args, **kwargs)
  File "C:\Users\topci\AppData\Local\Programs\Python\Python38\lib\site-packages\django\db\models\query.py", line 1421, in filter
    return self._filter_or_exclude(False, args, kwargs)
  File "C:\Users\topci\AppData\Local\Programs\Python\Python38\lib\site-packages\django\db\models\query.py", line 1439, in _filter_or_exclude
    clone._filter_or_exclude_inplace(negate, args, kwargs)
  File "C:\Users\topci\AppData\Local\Programs\Python\Python38\lib\site-packages\django\db\models\query.py", line 1446, in _filter_or_exclude_inplace
    self._query.add_q(Q(*args, **kwargs))
  File "C:\Users\topci\AppData\Local\Programs\Python\Python38\lib\site-packages\django\db\models\sql\query.py", line 1532, in add_q
    clause, _ = self._add_q(q_object, self.used_aliases)
  File "C:\Users\topci\AppData\Local\Programs\Python\Python38\lib\site-packages\django\db\models\sql\query.py", line 1562, in _add_q
    child_clause, needed_inner = self.build_filter(
  File "C:\Users\topci\AppData\Local\Programs\Python\Python38\lib\site-packages\django\db\models\sql\query.py", line 1478, in build_filter
    condition = self.build_lookup(lookups, col, value)
  File "C:\Users\topci\AppData\Local\Programs\Python\Python38\lib\site-packages\django\db\models\sql\query.py", line 1303, in build_lookup
    lookup = lookup_class(lhs, rhs)
  File "C:\Users\topci\AppData\Local\Programs\Python\Python38\lib\site-packages\django\db\models\lookups.py", line 27, in __init__
    self.rhs = self.get_prep_lookup()
  File "C:\Users\topci\AppData\Local\Programs\Python\Python38\lib\site-packages\django\db\models\fields\related_lookups.py", line 166, in get_prep_lookup
    self.rhs = target_field.get_prep_value(self.rhs)
  File "C:\Users\topci\AppData\Local\Programs\Python\Python38\lib\site-packages\django\db\models\fields\__init__.py", line 2020, in get_prep_value
    raise e.__class__(
TypeError: Field 'id' expected a number but got <SimpleLazyObject: <django.contrib.auth.models.AnonymousUser object at 0x000001E719D41A00>>.
OK: /
Traceback (most recent call last):
  File "C:\Users\topci\AppData\Local\Programs\Python\Python38\lib\site-packages\django\db\models\fields\__init__.py", line 2018, in get_prep_value
    return int(value)
TypeError: int() argument must be a string, a bytes-like object or a number, not 'SimpleLazyObject'

The above exception was the direct cause of the following exception:

Traceback (most recent call last):
  File "C:\Users\topci\AppData\Local\Programs\Python\Python38\lib\site-packages\django\core\handlers\exception.py", line 56, in inner
    response = get_response(request)
  File "C:\Users\topci\AppData\Local\Programs\Python\Python38\lib\site-packages\django\core\handlers\base.py", line 197, in _get_response
    response = wrapped_callback(request, *callback_args, **callback_kwargs)
  File "C:\Users\topci\Desktop\bitirmeProjesi\bitirmeProjem\urunler\views.py", line 188, in index
    uruns = Sepet.objects.filter(ekleyen = request.user, odendiMi = False)
  File "C:\Users\topci\AppData\Local\Programs\Python\Python38\lib\site-packages\django\db\models\manager.py", line 85, in manager_method
    return getattr(self.get_queryset(), name)(*args, **kwargs)
  File "C:\Users\topci\AppData\Local\Programs\Python\Python38\lib\site-packages\django\db\models\query.py", line 1421, in filter
    return self._filter_or_exclude(False, args, kwargs)
  File "C:\Users\topci\AppData\Local\Programs\Python\Python38\lib\site-packages\django\db\models\query.py", line 1439, in _filter_or_exclude
    clone._filter_or_exclude_inplace(negate, args, kwargs)
  File "C:\Users\topci\AppData\Local\Programs\Python\Python38\lib\site-packages\django\db\models\query.py", line 1446, in _filter_or_exclude_inplace
    self._query.add_q(Q(*args, **kwargs))
  File "C:\Users\topci\AppData\Local\Programs\Python\Python38\lib\site-packages\django\db\models\sql\query.py", line 1532, in add_q
    clause, _ = self._add_q(q_object, self.used_aliases)
  File "C:\Users\topci\AppData\Local\Programs\Python\Python38\lib\site-packages\django\db\models\sql\query.py", line 1562, in _add_q
    child_clause, needed_inner = self.build_filter(
  File "C:\Users\topci\AppData\Local\Programs\Python\Python38\lib\site-packages\django\db\models\sql\query.py", line 1478, in build_filter
    condition = self.build_lookup(lookups, col, value)
  File "C:\Users\topci\AppData\Local\Programs\Python\Python38\lib\site-packages\django\db\models\sql\query.py", line 1303, in build_lookup
    lookup = lookup_class(lhs, rhs)
  File "C:\Users\topci\AppData\Local\Programs\Python\Python38\lib\site-packages\django\db\models\lookups.py", line 27, in __init__
    self.rhs = self.get_prep_lookup()
  File "C:\Users\topci\AppData\Local\Programs\Python\Python38\lib\site-packages\django\db\models\fields\related_lookups.py", line 166, in get_prep_lookup
    self.rhs = target_field.get_prep_value(self.rhs)
  File "C:\Users\topci\AppData\Local\Programs\Python\Python38\lib\site-packages\django\db\models\fields\__init__.py", line 2020, in get_prep_value
    raise e.__class__(
TypeError: Field 'id' expected a number but got <SimpleLazyObject: <django.contrib.auth.models.AnonymousUser object at 0x000001E719D3F0D0>>.
OK: /
Traceback (most recent call last):
  File "C:\Users\topci\AppData\Local\Programs\Python\Python38\lib\site-packages\django\db\models\fields\__init__.py", line 2018, in get_prep_value
    return int(value)
TypeError: int() argument must be a string, a bytes-like object or a number, not 'SimpleLazyObject'

The above exception was the direct cause of the following exception:

Traceback (most recent call last):
  File "C:\Users\topci\AppData\Local\Programs\Python\Python38\lib\site-packages\django\core\handlers\exception.py", line 56, in inner
    response = get_response(request)
  File "C:\Users\topci\AppData\Local\Programs\Python\Python38\lib\site-packages\django\core\handlers\base.py", line 197, in _get_response
    response = wrapped_callback(request, *callback_args, **callback_kwargs)
  File "C:\Users\topci\Desktop\bitirmeProjesi\bitirmeProjem\urunler\views.py", line 188, in index
    uruns = Sepet.objects.filter(ekleyen = request.user, odendiMi = False)
  File "C:\Users\topci\AppData\Local\Programs\Python\Python38\lib\site-packages\django\db\models\manager.py", line 85, in manager_method
    return getattr(self.get_queryset(), name)(*args, **kwargs)
  File "C:\Users\topci\AppData\Local\Programs\Python\Python38\lib\site-packages\django\db\models\query.py", line 1421, in filter
    return self._filter_or_exclude(False, args, kwargs)
  File "C:\Users\topci\AppData\Local\Programs\Python\Python38\lib\site-packages\django\db\models\query.py", line 1439, in _filter_or_exclude
    clone._filter_or_exclude_inplace(negate, args, kwargs)
  File "C:\Users\topci\AppData\Local\Programs\Python\Python38\lib\site-packages\django\db\models\query.py", line 1446, in _filter_or_exclude_inplace
    self._query.add_q(Q(*args, **kwargs))
  File "C:\Users\topci\AppData\Local\Programs\Python\Python38\lib\site-packages\django\db\models\sql\query.py", line 1532, in add_q
    clause, _ = self._add_q(q_object, self.used_aliases)
  File "C:\Users\topci\AppData\Local\Programs\Python\Python38\lib\site-packages\django\db\models\sql\query.py", line 1562, in _add_q
    child_clause, needed_inner = self.build_filter(
  File "C:\Users\topci\AppData\Local\Programs\Python\Python38\lib\site-packages\django\db\models\sql\query.py", line 1478, in build_filter
    condition = self.build_lookup(lookups, col, value)
  File "C:\Users\topci\AppData\Local\Programs\Python\Python38\lib\site-packages\django\db\models\sql\query.py", line 1303, in build_lookup
    lookup = lookup_class(lhs, rhs)
  File "C:\Users\topci\AppData\Local\Programs\Python\Python38\lib\site-packages\django\db\models\lookups.py", line 27, in __init__
    self.rhs = self.get_prep_lookup()
  File "C:\Users\topci\AppData\Local\Programs\Python\Python38\lib\site-packages\django\db\models\fields\related_lookups.py", line 166, in get_prep_lookup
    self.rhs = target_field.get_prep_value(self.rhs)
  File "C:\Users\topci\AppData\Local\Programs\Python\Python38\lib\site-packages\django\db\models\fields\__init__.py", line 2020, in get_prep_value
    raise e.__class__(
TypeError: Field 'id' expected a number but got <SimpleLazyObject: <django.contrib.auth.models.AnonymousUser object at 0x000001E719D3F670>>.
OK: /
Traceback (most recent call last):
  File "C:\Users\topci\AppData\Local\Programs\Python\Python38\lib\site-packages\django\db\models\fields\__init__.py", line 2018, in get_prep_value
    return int(value)
TypeError: int() argument must be a string, a bytes-like object or a number, not 'SimpleLazyObject'

The above exception was the direct cause of the following exception:

Traceback (most recent call last):
  File "C:\Users\topci\AppData\Local\Programs\Python\Python38\lib\site-packages\django\core\handlers\exception.py", line 56, in inner
    response = get_response(request)
  File "C:\Users\topci\AppData\Local\Programs\Python\Python38\lib\site-packages\django\core\handlers\base.py", line 197, in _get_response
    response = wrapped_callback(request, *callback_args, **callback_kwargs)
  File "C:\Users\topci\Desktop\bitirmeProjesi\bitirmeProjem\urunler\views.py", line 188, in index
    uruns = Sepet.objects.filter(ekleyen = request.user, odendiMi = False)
  File "C:\Users\topci\AppData\Local\Programs\Python\Python38\lib\site-packages\django\db\models\manager.py", line 85, in manager_method
    return getattr(self.get_queryset(), name)(*args, **kwargs)
  File "C:\Users\topci\AppData\Local\Programs\Python\Python38\lib\site-packages\django\db\models\query.py", line 1421, in filter
    return self._filter_or_exclude(False, args, kwargs)
  File "C:\Users\topci\AppData\Local\Programs\Python\Python38\lib\site-packages\django\db\models\query.py", line 1439, in _filter_or_exclude
    clone._filter_or_exclude_inplace(negate, args, kwargs)
  File "C:\Users\topci\AppData\Local\Programs\Python\Python38\lib\site-packages\django\db\models\query.py", line 1446, in _filter_or_exclude_inplace
    self._query.add_q(Q(*args, **kwargs))
  File "C:\Users\topci\AppData\Local\Programs\Python\Python38\lib\site-packages\django\db\models\sql\query.py", line 1532, in add_q
    clause, _ = self._add_q(q_object, self.used_aliases)
  File "C:\Users\topci\AppData\Local\Programs\Python\Python38\lib\site-packages\django\db\models\sql\query.py", line 1562, in _add_q
    child_clause, needed_inner = self.build_filter(
  File "C:\Users\topci\AppData\Local\Programs\Python\Python38\lib\site-packages\django\db\models\sql\query.py", line 1478, in build_filter
    condition = self.build_lookup(lookups, col, value)
  File "C:\Users\topci\AppData\Local\Programs\Python\Python38\lib\site-packages\django\db\models\sql\query.py", line 1303, in build_lookup
    lookup = lookup_class(lhs, rhs)
  File "C:\Users\topci\AppData\Local\Programs\Python\Python38\lib\site-packages\django\db\models\lookups.py", line 27, in __init__
    self.rhs = self.get_prep_lookup()
  File "C:\Users\topci\AppData\Local\Programs\Python\Python38\lib\site-packages\django\db\models\fields\related_lookups.py", line 166, in get_prep_lookup
    self.rhs = target_field.get_prep_value(self.rhs)
  File "C:\Users\topci\AppData\Local\Programs\Python\Python38\lib\site-packages\django\db\models\fields\__init__.py", line 2020, in get_prep_value
    raise e.__class__(
TypeError: Field 'id' expected a number but got <SimpleLazyObject: <django.contrib.auth.models.AnonymousUser object at 0x000001E719D3FD30>>.
OK: /
Traceback (most recent call last):
  File "C:\Users\topci\AppData\Local\Programs\Python\Python38\lib\site-packages\django\db\models\fields\__init__.py", line 2018, in get_prep_value
    return int(value)
TypeError: int() argument must be a string, a bytes-like object or a number, not 'SimpleLazyObject'

The above exception was the direct cause of the following exception:

Traceback (most recent call last):
  File "C:\Users\topci\AppData\Local\Programs\Python\Python38\lib\site-packages\django\core\handlers\exception.py", line 56, in inner
    response = get_response(request)
  File "C:\Users\topci\AppData\Local\Programs\Python\Python38\lib\site-packages\django\core\handlers\base.py", line 197, in _get_response
    response = wrapped_callback(request, *callback_args, **callback_kwargs)
  File "C:\Users\topci\Desktop\bitirmeProjesi\bitirmeProjem\urunler\views.py", line 188, in index
    uruns = Sepet.objects.filter(ekleyen = request.user, odendiMi = False)
  File "C:\Users\topci\AppData\Local\Programs\Python\Python38\lib\site-packages\django\db\models\manager.py", line 85, in manager_method
    return getattr(self.get_queryset(), name)(*args, **kwargs)
  File "C:\Users\topci\AppData\Local\Programs\Python\Python38\lib\site-packages\django\db\models\query.py", line 1421, in filter
    return self._filter_or_exclude(False, args, kwargs)
  File "C:\Users\topci\AppData\Local\Programs\Python\Python38\lib\site-packages\django\db\models\query.py", line 1439, in _filter_or_exclude
    clone._filter_or_exclude_inplace(negate, args, kwargs)
  File "C:\Users\topci\AppData\Local\Programs\Python\Python38\lib\site-packages\django\db\models\query.py", line 1446, in _filter_or_exclude_inplace
    self._query.add_q(Q(*args, **kwargs))
  File "C:\Users\topci\AppData\Local\Programs\Python\Python38\lib\site-packages\django\db\models\sql\query.py", line 1532, in add_q
    clause, _ = self._add_q(q_object, self.used_aliases)
  File "C:\Users\topci\AppData\Local\Programs\Python\Python38\lib\site-packages\django\db\models\sql\query.py", line 1562, in _add_q
    child_clause, needed_inner = self.build_filter(
  File "C:\Users\topci\AppData\Local\Programs\Python\Python38\lib\site-packages\django\db\models\sql\query.py", line 1478, in build_filter
    condition = self.build_lookup(lookups, col, value)
  File "C:\Users\topci\AppData\Local\Programs\Python\Python38\lib\site-packages\django\db\models\sql\query.py", line 1303, in build_lookup
    lookup = lookup_class(lhs, rhs)
  File "C:\Users\topci\AppData\Local\Programs\Python\Python38\lib\site-packages\django\db\models\lookups.py", line 27, in __init__
    self.rhs = self.get_prep_lookup()
  File "C:\Users\topci\AppData\Local\Programs\Python\Python38\lib\site-packages\django\db\models\fields\related_lookups.py", line 166, in get_prep_lookup
    self.rhs = target_field.get_prep_value(self.rhs)
  File "C:\Users\topci\AppData\Local\Programs\Python\Python38\lib\site-packages\django\db\models\fields\__init__.py", line 2020, in get_prep_value
    raise e.__class__(
TypeError: Field 'id' expected a number but got <SimpleLazyObject: <django.contrib.auth.models.AnonymousUser object at 0x000001E719B7D730>>.
OK: /
Traceback (most recent call last):
  File "C:\Users\topci\AppData\Local\Programs\Python\Python38\lib\site-packages\django\db\models\fields\__init__.py", line 2018, in get_prep_value
    return int(value)
TypeError: int() argument must be a string, a bytes-like object or a number, not 'SimpleLazyObject'

The above exception was the direct cause of the following exception:

Traceback (most recent call last):
  File "C:\Users\topci\AppData\Local\Programs\Python\Python38\lib\site-packages\django\core\handlers\exception.py", line 56, in inner
    response = get_response(request)
  File "C:\Users\topci\AppData\Local\Programs\Python\Python38\lib\site-packages\django\core\handlers\base.py", line 197, in _get_response
    response = wrapped_callback(request, *callback_args, **callback_kwargs)
  File "C:\Users\topci\Desktop\bitirmeProjesi\bitirmeProjem\urunler\views.py", line 188, in index
    uruns = Sepet.objects.filter(ekleyen = request.user, odendiMi = False)
  File "C:\Users\topci\AppData\Local\Programs\Python\Python38\lib\site-packages\django\db\models\manager.py", line 85, in manager_method
    return getattr(self.get_queryset(), name)(*args, **kwargs)
  File "C:\Users\topci\AppData\Local\Programs\Python\Python38\lib\site-packages\django\db\models\query.py", line 1421, in filter
    return self._filter_or_exclude(False, args, kwargs)
  File "C:\Users\topci\AppData\Local\Programs\Python\Python38\lib\site-packages\django\db\models\query.py", line 1439, in _filter_or_exclude
    clone._filter_or_exclude_inplace(negate, args, kwargs)
  File "C:\Users\topci\AppData\Local\Programs\Python\Python38\lib\site-packages\django\db\models\query.py", line 1446, in _filter_or_exclude_inplace
    self._query.add_q(Q(*args, **kwargs))
  File "C:\Users\topci\AppData\Local\Programs\Python\Python38\lib\site-packages\django\db\models\sql\query.py", line 1532, in add_q
    clause, _ = self._add_q(q_object, self.used_aliases)
  File "C:\Users\topci\AppData\Local\Programs\Python\Python38\lib\site-packages\django\db\models\sql\query.py", line 1562, in _add_q
    child_clause, needed_inner = self.build_filter(
  File "C:\Users\topci\AppData\Local\Programs\Python\Python38\lib\site-packages\django\db\models\sql\query.py", line 1478, in build_filter
    condition = self.build_lookup(lookups, col, value)
  File "C:\Users\topci\AppData\Local\Programs\Python\Python38\lib\site-packages\django\db\models\sql\query.py", line 1303, in build_lookup
    lookup = lookup_class(lhs, rhs)
  File "C:\Users\topci\AppData\Local\Programs\Python\Python38\lib\site-packages\django\db\models\lookups.py", line 27, in __init__
    self.rhs = self.get_prep_lookup()
  File "C:\Users\topci\AppData\Local\Programs\Python\Python38\lib\site-packages\django\db\models\fields\related_lookups.py", line 166, in get_prep_lookup
    self.rhs = target_field.get_prep_value(self.rhs)
  File "C:\Users\topci\AppData\Local\Programs\Python\Python38\lib\site-packages\django\db\models\fields\__init__.py", line 2020, in get_prep_value
    raise e.__class__(
TypeError: Field 'id' expected a number but got <SimpleLazyObject: <django.contrib.auth.models.AnonymousUser object at 0x000001E719D49FD0>>.
OK: /
Traceback (most recent call last):
  File "C:\Users\topci\AppData\Local\Programs\Python\Python38\lib\site-packages\django\db\models\fields\__init__.py", line 2018, in get_prep_value
    return int(value)
TypeError: int() argument must be a string, a bytes-like object or a number, not 'SimpleLazyObject'

The above exception was the direct cause of the following exception:

Traceback (most recent call last):
  File "C:\Users\topci\AppData\Local\Programs\Python\Python38\lib\site-packages\django\core\handlers\exception.py", line 56, in inner
    response = get_response(request)
  File "C:\Users\topci\AppData\Local\Programs\Python\Python38\lib\site-packages\django\core\handlers\base.py", line 197, in _get_response
    response = wrapped_callback(request, *callback_args, **callback_kwargs)
  File "C:\Users\topci\Desktop\bitirmeProjesi\bitirmeProjem\urunler\views.py", line 188, in index
    uruns = Sepet.objects.filter(ekleyen = request.user, odendiMi = False)
  File "C:\Users\topci\AppData\Local\Programs\Python\Python38\lib\site-packages\django\db\models\manager.py", line 85, in manager_method
    return getattr(self.get_queryset(), name)(*args, **kwargs)
  File "C:\Users\topci\AppData\Local\Programs\Python\Python38\lib\site-packages\django\db\models\query.py", line 1421, in filter
    return self._filter_or_exclude(False, args, kwargs)
  File "C:\Users\topci\AppData\Local\Programs\Python\Python38\lib\site-packages\django\db\models\query.py", line 1439, in _filter_or_exclude
    clone._filter_or_exclude_inplace(negate, args, kwargs)
  File "C:\Users\topci\AppData\Local\Programs\Python\Python38\lib\site-packages\django\db\models\query.py", line 1446, in _filter_or_exclude_inplace
    self._query.add_q(Q(*args, **kwargs))
  File "C:\Users\topci\AppData\Local\Programs\Python\Python38\lib\site-packages\django\db\models\sql\query.py", line 1532, in add_q
    clause, _ = self._add_q(q_object, self.used_aliases)
  File "C:\Users\topci\AppData\Local\Programs\Python\Python38\lib\site-packages\django\db\models\sql\query.py", line 1562, in _add_q
    child_clause, needed_inner = self.build_filter(
  File "C:\Users\topci\AppData\Local\Programs\Python\Python38\lib\site-packages\django\db\models\sql\query.py", line 1478, in build_filter
    condition = self.build_lookup(lookups, col, value)
  File "C:\Users\topci\AppData\Local\Programs\Python\Python38\lib\site-packages\django\db\models\sql\query.py", line 1303, in build_lookup
    lookup = lookup_class(lhs, rhs)
  File "C:\Users\topci\AppData\Local\Programs\Python\Python38\lib\site-packages\django\db\models\lookups.py", line 27, in __init__
    self.rhs = self.get_prep_lookup()
  File "C:\Users\topci\AppData\Local\Programs\Python\Python38\lib\site-packages\django\db\models\fields\related_lookups.py", line 166, in get_prep_lookup
    self.rhs = target_field.get_prep_value(self.rhs)
  File "C:\Users\topci\AppData\Local\Programs\Python\Python38\lib\site-packages\django\db\models\fields\__init__.py", line 2020, in get_prep_value
    raise e.__class__(
TypeError: Field 'id' expected a number but got <SimpleLazyObject: <django.contrib.auth.models.AnonymousUser object at 0x000001E719D3F9A0>>.
OK: /
Traceback (most recent call last):
  File "C:\Users\topci\AppData\Local\Programs\Python\Python38\lib\site-packages\django\db\models\fields\__init__.py", line 2018, in get_prep_value
    return int(value)
TypeError: int() argument must be a string, a bytes-like object or a number, not 'SimpleLazyObject'

The above exception was the direct cause of the following exception:

Traceback (most recent call last):
  File "C:\Users\topci\AppData\Local\Programs\Python\Python38\lib\site-packages\django\core\handlers\exception.py", line 56, in inner
    response = get_response(request)
  File "C:\Users\topci\AppData\Local\Programs\Python\Python38\lib\site-packages\django\core\handlers\base.py", line 197, in _get_response
    response = wrapped_callback(request, *callback_args, **callback_kwargs)
  File "C:\Users\topci\Desktop\bitirmeProjesi\bitirmeProjem\urunler\views.py", line 188, in index
    uruns = Sepet.objects.filter(ekleyen = request.user, odendiMi = False)
  File "C:\Users\topci\AppData\Local\Programs\Python\Python38\lib\site-packages\django\db\models\manager.py", line 85, in manager_method
    return getattr(self.get_queryset(), name)(*args, **kwargs)
  File "C:\Users\topci\AppData\Local\Programs\Python\Python38\lib\site-packages\django\db\models\query.py", line 1421, in filter
    return self._filter_or_exclude(False, args, kwargs)
  File "C:\Users\topci\AppData\Local\Programs\Python\Python38\lib\site-packages\django\db\models\query.py", line 1439, in _filter_or_exclude
    clone._filter_or_exclude_inplace(negate, args, kwargs)
  File "C:\Users\topci\AppData\Local\Programs\Python\Python38\lib\site-packages\django\db\models\query.py", line 1446, in _filter_or_exclude_inplace
    self._query.add_q(Q(*args, **kwargs))
  File "C:\Users\topci\AppData\Local\Programs\Python\Python38\lib\site-packages\django\db\models\sql\query.py", line 1532, in add_q
    clause, _ = self._add_q(q_object, self.used_aliases)
  File "C:\Users\topci\AppData\Local\Programs\Python\Python38\lib\site-packages\django\db\models\sql\query.py", line 1562, in _add_q
    child_clause, needed_inner = self.build_filter(
  File "C:\Users\topci\AppData\Local\Programs\Python\Python38\lib\site-packages\django\db\models\sql\query.py", line 1478, in build_filter
    condition = self.build_lookup(lookups, col, value)
  File "C:\Users\topci\AppData\Local\Programs\Python\Python38\lib\site-packages\django\db\models\sql\query.py", line 1303, in build_lookup
    lookup = lookup_class(lhs, rhs)
  File "C:\Users\topci\AppData\Local\Programs\Python\Python38\lib\site-packages\django\db\models\lookups.py", line 27, in __init__
    self.rhs = self.get_prep_lookup()
  File "C:\Users\topci\AppData\Local\Programs\Python\Python38\lib\site-packages\django\db\models\fields\related_lookups.py", line 166, in get_prep_lookup
    self.rhs = target_field.get_prep_value(self.rhs)
  File "C:\Users\topci\AppData\Local\Programs\Python\Python38\lib\site-packages\django\db\models\fields\__init__.py", line 2020, in get_prep_value
    raise e.__class__(
TypeError: Field 'id' expected a number but got <SimpleLazyObject: <django.contrib.auth.models.AnonymousUser object at 0x000001E719EC7FD0>>.
OK: /
Traceback (most recent call last):
  File "C:\Users\topci\AppData\Local\Programs\Python\Python38\lib\site-packages\django\db\models\fields\__init__.py", line 2018, in get_prep_value
    return int(value)
TypeError: int() argument must be a string, a bytes-like object or a number, not 'SimpleLazyObject'

The above exception was the direct cause of the following exception:

Traceback (most recent call last):
  File "C:\Users\topci\AppData\Local\Programs\Python\Python38\lib\site-packages\django\core\handlers\exception.py", line 56, in inner
    response = get_response(request)
  File "C:\Users\topci\AppData\Local\Programs\Python\Python38\lib\site-packages\django\core\handlers\base.py", line 197, in _get_response
    response = wrapped_callback(request, *callback_args, **callback_kwargs)
  File "C:\Users\topci\Desktop\bitirmeProjesi\bitirmeProjem\urunler\views.py", line 188, in index
    uruns = Sepet.objects.filter(ekleyen = request.user, odendiMi = False)
  File "C:\Users\topci\AppData\Local\Programs\Python\Python38\lib\site-packages\django\db\models\manager.py", line 85, in manager_method
    return getattr(self.get_queryset(), name)(*args, **kwargs)
  File "C:\Users\topci\AppData\Local\Programs\Python\Python38\lib\site-packages\django\db\models\query.py", line 1421, in filter
    return self._filter_or_exclude(False, args, kwargs)
  File "C:\Users\topci\AppData\Local\Programs\Python\Python38\lib\site-packages\django\db\models\query.py", line 1439, in _filter_or_exclude
    clone._filter_or_exclude_inplace(negate, args, kwargs)
  File "C:\Users\topci\AppData\Local\Programs\Python\Python38\lib\site-packages\django\db\models\query.py", line 1446, in _filter_or_exclude_inplace
    self._query.add_q(Q(*args, **kwargs))
  File "C:\Users\topci\AppData\Local\Programs\Python\Python38\lib\site-packages\django\db\models\sql\query.py", line 1532, in add_q
    clause, _ = self._add_q(q_object, self.used_aliases)
  File "C:\Users\topci\AppData\Local\Programs\Python\Python38\lib\site-packages\django\db\models\sql\query.py", line 1562, in _add_q
    child_clause, needed_inner = self.build_filter(
  File "C:\Users\topci\AppData\Local\Programs\Python\Python38\lib\site-packages\django\db\models\sql\query.py", line 1478, in build_filter
    condition = self.build_lookup(lookups, col, value)
  File "C:\Users\topci\AppData\Local\Programs\Python\Python38\lib\site-packages\django\db\models\sql\query.py", line 1303, in build_lookup
    lookup = lookup_class(lhs, rhs)
  File "C:\Users\topci\AppData\Local\Programs\Python\Python38\lib\site-packages\django\db\models\lookups.py", line 27, in __init__
    self.rhs = self.get_prep_lookup()
  File "C:\Users\topci\AppData\Local\Programs\Python\Python38\lib\site-packages\django\db\models\fields\related_lookups.py", line 166, in get_prep_lookup
    self.rhs = target_field.get_prep_value(self.rhs)
  File "C:\Users\topci\AppData\Local\Programs\Python\Python38\lib\site-packages\django\db\models\fields\__init__.py", line 2020, in get_prep_value
    raise e.__class__(
TypeError: Field 'id' expected a number but got <SimpleLazyObject: <django.contrib.auth.models.AnonymousUser object at 0x000001E719C528E0>>.
OK: /
Traceback (most recent call last):
  File "C:\Users\topci\AppData\Local\Programs\Python\Python38\lib\site-packages\django\db\models\fields\__init__.py", line 2018, in get_prep_value
    return int(value)
TypeError: int() argument must be a string, a bytes-like object or a number, not 'SimpleLazyObject'

The above exception was the direct cause of the following exception:

Traceback (most recent call last):
  File "C:\Users\topci\AppData\Local\Programs\Python\Python38\lib\site-packages\django\core\handlers\exception.py", line 56, in inner
    response = get_response(request)
  File "C:\Users\topci\AppData\Local\Programs\Python\Python38\lib\site-packages\django\core\handlers\base.py", line 197, in _get_response
    response = wrapped_callback(request, *callback_args, **callback_kwargs)
  File "C:\Users\topci\Desktop\bitirmeProjesi\bitirmeProjem\urunler\views.py", line 188, in index
    uruns = Sepet.objects.filter(ekleyen = request.user, odendiMi = False)
  File "C:\Users\topci\AppData\Local\Programs\Python\Python38\lib\site-packages\django\db\models\manager.py", line 85, in manager_method
    return getattr(self.get_queryset(), name)(*args, **kwargs)
  File "C:\Users\topci\AppData\Local\Programs\Python\Python38\lib\site-packages\django\db\models\query.py", line 1421, in filter
    return self._filter_or_exclude(False, args, kwargs)
  File "C:\Users\topci\AppData\Local\Programs\Python\Python38\lib\site-packages\django\db\models\query.py", line 1439, in _filter_or_exclude
    clone._filter_or_exclude_inplace(negate, args, kwargs)
  File "C:\Users\topci\AppData\Local\Programs\Python\Python38\lib\site-packages\django\db\models\query.py", line 1446, in _filter_or_exclude_inplace
    self._query.add_q(Q(*args, **kwargs))
  File "C:\Users\topci\AppData\Local\Programs\Python\Python38\lib\site-packages\django\db\models\sql\query.py", line 1532, in add_q
    clause, _ = self._add_q(q_object, self.used_aliases)
  File "C:\Users\topci\AppData\Local\Programs\Python\Python38\lib\site-packages\django\db\models\sql\query.py", line 1562, in _add_q
    child_clause, needed_inner = self.build_filter(
  File "C:\Users\topci\AppData\Local\Programs\Python\Python38\lib\site-packages\django\db\models\sql\query.py", line 1478, in build_filter
    condition = self.build_lookup(lookups, col, value)
  File "C:\Users\topci\AppData\Local\Programs\Python\Python38\lib\site-packages\django\db\models\sql\query.py", line 1303, in build_lookup
    lookup = lookup_class(lhs, rhs)
  File "C:\Users\topci\AppData\Local\Programs\Python\Python38\lib\site-packages\django\db\models\lookups.py", line 27, in __init__
    self.rhs = self.get_prep_lookup()
  File "C:\Users\topci\AppData\Local\Programs\Python\Python38\lib\site-packages\django\db\models\fields\related_lookups.py", line 166, in get_prep_lookup
    self.rhs = target_field.get_prep_value(self.rhs)
  File "C:\Users\topci\AppData\Local\Programs\Python\Python38\lib\site-packages\django\db\models\fields\__init__.py", line 2020, in get_prep_value
    raise e.__class__(
TypeError: Field 'id' expected a number but got <SimpleLazyObject: <django.contrib.auth.models.AnonymousUser object at 0x000001E719E71E20>>.
OK: /
Traceback (most recent call last):
  File "C:\Users\topci\AppData\Local\Programs\Python\Python38\lib\site-packages\django\db\models\fields\__init__.py", line 2018, in get_prep_value
    return int(value)
TypeError: int() argument must be a string, a bytes-like object or a number, not 'SimpleLazyObject'

The above exception was the direct cause of the following exception:

Traceback (most recent call last):
  File "C:\Users\topci\AppData\Local\Programs\Python\Python38\lib\site-packages\django\core\handlers\exception.py", line 56, in inner
    response = get_response(request)
  File "C:\Users\topci\AppData\Local\Programs\Python\Python38\lib\site-packages\django\core\handlers\base.py", line 197, in _get_response
    response = wrapped_callback(request, *callback_args, **callback_kwargs)
  File "C:\Users\topci\Desktop\bitirmeProjesi\bitirmeProjem\urunler\views.py", line 188, in index
    uruns = Sepet.objects.filter(ekleyen = request.user, odendiMi = False)
  File "C:\Users\topci\AppData\Local\Programs\Python\Python38\lib\site-packages\django\db\models\manager.py", line 85, in manager_method
    return getattr(self.get_queryset(), name)(*args, **kwargs)
  File "C:\Users\topci\AppData\Local\Programs\Python\Python38\lib\site-packages\django\db\models\query.py", line 1421, in filter
    return self._filter_or_exclude(False, args, kwargs)
  File "C:\Users\topci\AppData\Local\Programs\Python\Python38\lib\site-packages\django\db\models\query.py", line 1439, in _filter_or_exclude
    clone._filter_or_exclude_inplace(negate, args, kwargs)
  File "C:\Users\topci\AppData\Local\Programs\Python\Python38\lib\site-packages\django\db\models\query.py", line 1446, in _filter_or_exclude_inplace
    self._query.add_q(Q(*args, **kwargs))
  File "C:\Users\topci\AppData\Local\Programs\Python\Python38\lib\site-packages\django\db\models\sql\query.py", line 1532, in add_q
    clause, _ = self._add_q(q_object, self.used_aliases)
  File "C:\Users\topci\AppData\Local\Programs\Python\Python38\lib\site-packages\django\db\models\sql\query.py", line 1562, in _add_q
    child_clause, needed_inner = self.build_filter(
  File "C:\Users\topci\AppData\Local\Programs\Python\Python38\lib\site-packages\django\db\models\sql\query.py", line 1478, in build_filter
    condition = self.build_lookup(lookups, col, value)
  File "C:\Users\topci\AppData\Local\Programs\Python\Python38\lib\site-packages\django\db\models\sql\query.py", line 1303, in build_lookup
    lookup = lookup_class(lhs, rhs)
  File "C:\Users\topci\AppData\Local\Programs\Python\Python38\lib\site-packages\django\db\models\lookups.py", line 27, in __init__
    self.rhs = self.get_prep_lookup()
  File "C:\Users\topci\AppData\Local\Programs\Python\Python38\lib\site-packages\django\db\models\fields\related_lookups.py", line 166, in get_prep_lookup
    self.rhs = target_field.get_prep_value(self.rhs)
  File "C:\Users\topci\AppData\Local\Programs\Python\Python38\lib\site-packages\django\db\models\fields\__init__.py", line 2020, in get_prep_value
    raise e.__class__(
TypeError: Field 'id' expected a number but got <SimpleLazyObject: <django.contrib.auth.models.AnonymousUser object at 0x000001E719C52310>>.
OK: /
Traceback (most recent call last):
  File "C:\Users\topci\AppData\Local\Programs\Python\Python38\lib\site-packages\django\db\models\fields\__init__.py", line 2018, in get_prep_value
    return int(value)
TypeError: int() argument must be a string, a bytes-like object or a number, not 'SimpleLazyObject'

The above exception was the direct cause of the following exception:

Traceback (most recent call last):
  File "C:\Users\topci\AppData\Local\Programs\Python\Python38\lib\site-packages\django\core\handlers\exception.py", line 56, in inner
    response = get_response(request)
  File "C:\Users\topci\AppData\Local\Programs\Python\Python38\lib\site-packages\django\core\handlers\base.py", line 197, in _get_response
    response = wrapped_callback(request, *callback_args, **callback_kwargs)
  File "C:\Users\topci\Desktop\bitirmeProjesi\bitirmeProjem\urunler\views.py", line 188, in index
    uruns = Sepet.objects.filter(ekleyen = request.user, odendiMi = False)
  File "C:\Users\topci\AppData\Local\Programs\Python\Python38\lib\site-packages\django\db\models\manager.py", line 85, in manager_method
    return getattr(self.get_queryset(), name)(*args, **kwargs)
  File "C:\Users\topci\AppData\Local\Programs\Python\Python38\lib\site-packages\django\db\models\query.py", line 1421, in filter
    return self._filter_or_exclude(False, args, kwargs)
  File "C:\Users\topci\AppData\Local\Programs\Python\Python38\lib\site-packages\django\db\models\query.py", line 1439, in _filter_or_exclude
    clone._filter_or_exclude_inplace(negate, args, kwargs)
  File "C:\Users\topci\AppData\Local\Programs\Python\Python38\lib\site-packages\django\db\models\query.py", line 1446, in _filter_or_exclude_inplace
    self._query.add_q(Q(*args, **kwargs))
  File "C:\Users\topci\AppData\Local\Programs\Python\Python38\lib\site-packages\django\db\models\sql\query.py", line 1532, in add_q
    clause, _ = self._add_q(q_object, self.used_aliases)
  File "C:\Users\topci\AppData\Local\Programs\Python\Python38\lib\site-packages\django\db\models\sql\query.py", line 1562, in _add_q
    child_clause, needed_inner = self.build_filter(
  File "C:\Users\topci\AppData\Local\Programs\Python\Python38\lib\site-packages\django\db\models\sql\query.py", line 1478, in build_filter
    condition = self.build_lookup(lookups, col, value)
  File "C:\Users\topci\AppData\Local\Programs\Python\Python38\lib\site-packages\django\db\models\sql\query.py", line 1303, in build_lookup
    lookup = lookup_class(lhs, rhs)
  File "C:\Users\topci\AppData\Local\Programs\Python\Python38\lib\site-packages\django\db\models\lookups.py", line 27, in __init__
    self.rhs = self.get_prep_lookup()
  File "C:\Users\topci\AppData\Local\Programs\Python\Python38\lib\site-packages\django\db\models\fields\related_lookups.py", line 166, in get_prep_lookup
    self.rhs = target_field.get_prep_value(self.rhs)
  File "C:\Users\topci\AppData\Local\Programs\Python\Python38\lib\site-packages\django\db\models\fields\__init__.py", line 2020, in get_prep_value
    raise e.__class__(
TypeError: Field 'id' expected a number but got <SimpleLazyObject: <django.contrib.auth.models.AnonymousUser object at 0x000001E719E71490>>.
C:\Users\topci\Desktop\bitirmeProjesi\bitirmeProjem\urunler\views.py changed, reloading.
Watching for file changes with StatReloader
C:\Users\topci\Desktop\bitirmeProjesi\bitirmeProjem\urunler\views.py changed, reloading.
Watching for file changes with StatReloader
C:\Users\topci\Desktop\bitirmeProjesi\bitirmeProjem\urunler\views.py changed, reloading.
Watching for file changes with StatReloader
C:\Users\topci\Desktop\bitirmeProjesi\bitirmeProjem\urunler\views.py changed, reloading.
Watching for file changes with StatReloader
C:\Users\topci\Desktop\bitirmeProjesi\bitirmeProjem\urunler\views.py changed, reloading.
Watching for file changes with StatReloader
C:\Users\topci\Desktop\bitirmeProjesi\bitirmeProjem\urunler\views.py changed, reloading.
Watching for file changes with StatReloader
C:\Users\topci\Desktop\bitirmeProjesi\bitirmeProjem\urunler\views.py changed, reloading.
Watching for file changes with StatReloader
C:\Users\topci\Desktop\bitirmeProjesi\bitirmeProjem\urunler\views.py changed, reloading.
Watching for file changes with StatReloader
C:\Users\topci\Desktop\bitirmeProjesi\bitirmeProjem\urunler\views.py changed, reloading.
Watching for file changes with StatReloader
C:\Users\topci\Desktop\bitirmeProjesi\bitirmeProjem\urunler\views.py changed, reloading.
Watching for file changes with StatReloader
C:\Users\topci\Desktop\bitirmeProjesi\bitirmeProjem\urunler\views.py changed, reloading.
Watching for file changes with StatReloader
C:\Users\topci\Desktop\bitirmeProjesi\bitirmeProjem\urunler\views.py changed, reloading.
Watching for file changes with StatReloader
C:\Users\topci\Desktop\bitirmeProjesi\bitirmeProjem\urunler\views.py changed, reloading.
Watching for file changes with StatReloader
C:\Users\topci\Desktop\bitirmeProjesi\bitirmeProjem\urunler\views.py changed, reloading.
Watching for file changes with StatReloader
